Workbook

Sheet Dashboard
A1: Freelander BT53 AKJ - Dashboard
A2: Auto-updated from other sheets. Yellow cells are manual entries.
A4: Vehicle Status | D4: Spend (Year to Date)
A5: Registration | B5: BT53 AKJ | D5: Total spend YTD | E5: =SUMIFS('Expenses Log'!E:E,'Expenses Log'!A:A,">="&DATE(YEAR(TODAY()),1,1)) -> 5146.71 | F5: =E5/12 -> 428.8925
A6: Current mileage (manual) | B6: 80705 | C6: Update after each fill-up | D6: Fuel YTD | E6: =SUMIFS('Expenses Log'!E:E,'Expenses Log'!A:A,">="&DATE(YEAR(TODAY()),1,1),'Expenses Log'!B:B,"Fuel") -> 725.7
A7: Latest logged mileage | B7: =IF(MAX(0,IFERROR(MAX('Fuel Log'!B:B),0),IFERROR(MAX('Tyre Log'!B:B),0),IFERROR(MAX('Wash Log'!E:E),0))=0,"—",MAX(0,IFERROR(MAX('Fuel Log'!B:B),0),IFERROR(MAX('Tyre Log'!B:B),0),IFERROR(MAX('Wash Log'!E:E),0))) -> 80712 | C7: Max across fuel/tyre/wash logs | D7: Service & repairs YTD | E7: =SUMIFS('Expenses Log'!E:E,'Expenses Log'!A:A,">="&DATE(YEAR(TODAY()),1,1),'Expenses Log'!B:B,"Service")+SUMIFS('Expenses Log'!E:E,'Expenses Log'!A:A,">="&DATE(YEAR(TODAY()),1,1),'Expenses Log'!B:B,"Repair")+SUMIFS('Expenses Log'!E:E,'Expenses Log'!A:A,">="&DATE(YEAR(TODAY()),1,1),'Expenses Log'!B:B,"Parts") -> 603.99
A8: Miles since purchase | B8: =B6-76632 -> 4073 | D8: Insurance + tax + MOT YTD | E8: =SUMIFS('Expenses Log'!E:E,'Expenses Log'!A:A,">="&DATE(YEAR(TODAY()),1,1),'Expenses Log'!B:B,"Insurance")+SUMIFS('Expenses Log'!E:E,'Expenses Log'!A:A,">="&DATE(YEAR(TODAY()),1,1),'Expenses Log'!B:B,"Tax")+SUMIFS('Expenses Log'!E:E,'Expenses Log'!A:A,">="&DATE(YEAR(TODAY()),1,1),'Expenses Log'!B:B,"MOT") -> 1005.14
D9: Total spend since purchase | E9: =SUMIFS('Expenses Log'!E:E,'Expenses Log'!A:A,">="&DATE(2026,3,14)) -> 5146.71
A10: Renewals & Due Dates | D10: Cost per mile (since purchase) | E10: =IFERROR(E9/(B6-76632),"—") -> 1.2636165
A11: MOT expiry | B11: =DATE(2026,8,6) -> 46240
A12: Days to MOT | B12: =B11-TODAY() -> 26 | D12: Fuel Economy
A13: Insurance expiry | B13: =DATE(2027,3,15) -> 46461 | D13: Average MPG | E13: =IFERROR(AVERAGE('Fuel Log'!G:G),"—") -> 28.775701
A14: Days to insurance renewal | B14: =B13-TODAY() -> 247 | D14: Best MPG | E14: =IF(COUNT('Fuel Log'!G:G)=0,"—",MAX('Fuel Log'!G:G)) -> 32.153092
A15: Road tax expiry | B15: =DATE(2027,2,28) -> 46446 | C15: Verify at gov.uk/check-vehicle-tax | D15: Worst MPG | E15: =IF(COUNT('Fuel Log'!G:G)=0,"—",MIN('Fuel Log'!G:G)) -> 24.490227
A16: Days to tax renewal | B16: =B15-TODAY() -> 232 | D16: Total litres pumped | E16: =IF(SUM('Fuel Log'!C:C)=0,"—",SUM('Fuel Log'!C:C)) -> 1112.94
A17: Next service target (date) | B17: =IFERROR(INDEX('Service History'!I:I,MATCH(MAX('Service History'!I:I),'Service History'!I:I,0)),"—") -> 46576 | D17: Avg price per litre | E17: =IFERROR(AVERAGE('Fuel Log'!D:D),"—") -> 1.5949231
A18: Next service target (miles) | B18: =IFERROR(INDEX('Service History'!H:H,MATCH(MAX('Service History'!H:H),'Service History'!H:H,0)),"—") -> 87500 | D18: Last fill date | E18: =IF(COUNT('Fuel Log'!A:A)=0,"—",MAX('Fuel Log'!A:A)) -> 46213
A20: Action Items
A21: Open DIY tasks | B21: =COUNTIF('DIY To-Do'!E:E,"Open") -> 5 | D21: In-progress DIY | E21: =COUNTIF('DIY To-Do'!E:E,"In Progress") -> 0
A22: Open workshop tasks | B22: =COUNTIF('Workshop To-Do'!E:E,"Open") -> 1 | D22: Scheduled workshop tasks | E22: =COUNTIF('Workshop To-Do'!E:E,"Scheduled") -> 0
A23: High-priority open (DIY+Workshop) | B23: =COUNTIFS('DIY To-Do'!A:A,"High",'DIY To-Do'!E:E,"Open")+COUNTIFS('Workshop To-Do'!A:A,"High",'Workshop To-Do'!E:E,"Open") -> 0 | D23: Open issues on watchlist | E23: =COUNTIF('Issues Watchlist'!H:H,"Monitoring")+COUNTIF('Issues Watchlist'!H:H,"Worsening") -> 5
A25: Regular Checks Status
A26: Checks overdue | B26: =COUNTIF('Regular Checks'!F:F,"Overdue") -> 7 | D26: Checks due soon | E26: =COUNTIF('Regular Checks'!F:F,"Due Soon") -> 3
A27: Checks OK | B27: =COUNTIF('Regular Checks'!F:F,"OK") -> 7 | D27: Last wash | E27: =IF(COUNT('Wash Log'!A:A)=0,"—",MAX('Wash Log'!A:A)) -> 46203
A28: Days since last wash | B28: =IF(COUNT('Wash Log'!A:A)=0,"—",TODAY()-MAX('Wash Log'!A:A)) -> 11 | D28: Last tyre check | E28: =IF(COUNT('Tyre Log'!A:A)=0,"—",MAX('Tyre Log'!A:A)) -> 46165

Sheet Vehicle Info
A1: Vehicle Information & Reference
A2: Static reference data. Update only when things actually change.
A4: Identification
A5: Registration number | B5: BT53 AKJ
A6: Make | B6: Land Rover
A7: Model | B7: Freelander 1 — 1.8 SE Station Wagon 5dr
A8: Year / registration | B8: 2003 (53 reg)
A9: Colour | B9: Navy Blue
A10: Body | B10: 5-door SUV
A11: V5C document reference | B11: 26005 504 9307 | C11: From new keeper slip
A12: Date of purchase | B12: 14 March 2026 | C12: Per user record
A13: Purchased from | B13: Lee (private sale), Purley
A14: Purchase price | B14: 1700 | C14: £50 off £1,750 asking for hand brake cables/adjustement
A15: Purchase mileage | B15: 76,632 mi
A16: Engine & Drivetrain
A17: Engine | B17: Rover K-series 1.8 petrol | C17: Known for head gasket issues - monitor
A18: Engine size | B18: 1796 cc
A19: Fuel type | B19: Petrol - E10 unleaded
A20: Gearbox | B20: Manual 5-speed
A21: Drivetrain | B21: AWD via viscous coupling (VCU) | C21: Test on tight turns - no shudder good
A22: Fuel tank capacity | B22: 61 litres
A23: Real-world MPG (mixed) | B23: 25-30 | C23: Confirmed on first fill
A24: Estimated range per tank | B24: ~350-380 miles
A25: Immobiliser | B25: Engine immobiliser (factory)
A26: Fluids & Specs (verify in handbook)
A27: Engine oil spec | B27: 5W-30 or 10W-40 semi-synthetic, ACEA A3/B3 | C27: K-series - verify in handbook
A28: Engine oil capacity | B28: ~4.5 L with filter | C28: Approximate - verify
A29: Coolant spec | B29: OAT coolant (red/pink), e.g. Havoline XLC | C29: IMPORTANT: K-series needs OAT - do not mix with blue/green IAT
A30: Coolant capacity | B30: ~7 litres | C30: Approximate - verify
A31: Brake fluid | B31: DOT 4
A32: Transmission oil | B32: MTF 94 (manual gearbox) | C32: Verify spec
A33: Spark plug type | B33: Check handbook | C33: Gap and torque per handbook
A34: Air filter part # | B34: TBD | C34: Log when first replaced
A35: Oil filter part # | B35: TBD | C35: Log when first replaced
A36: Tyres (verify from door jamb sticker)
A37: Tyre size | B37: 215/65 R16 (common OE for 1.8 SE) | C37: Check sidewall of fitted tyres
A38: Recommended pressure - normal load front | B38: 32 PSI | C38: Verify from door jamb sticker / handbook
A39: Recommended pressure - normal load rear | B39: 32 PSI | C39: Verify from door jamb sticker / handbook
A40: Recommended pressure - full load front | B40: 35 PSI | C40: Verify from door jamb sticker / handbook
A41: Recommended pressure - full load rear | B41: 35 PSI | C41: Verify from door jamb sticker / handbook
...

Sheet Expenses Log
A1: Expenses Log
A2: Every expense goes here. Feeds Dashboard and Budget. Use the Category column strictly as listed.
A4: Date | B4: Category | C4: Sub-category | D4: Vendor | E4: Amount (£) | F4: Mileage | G4: Payment Method | H4: Notes | I4: Running total | K4: Categories (use exactly)
A5: 46095 | B5: Purchase | C5: Vehicle purchase | D5: Lee (private) | E5: 1700 | F5: 76632 | G5: Bank transfer | H5: Purchase price, £50 off asking | I5: =SUM($E$5:E5) -> 1700 | K5: Fuel
A6: 46095 | B6: Insurance | C6: Annual premium | D6: Admiral / EUI Ltd | E6: 517.14 | F6: 76632 | G6: Credit card | H6: Policy P77904683, 15/03/26 - 15/03/27, includes AA roadside £38.35 | I6: =SUM($E$5:E6) -> 2217.14 | K6: Service
A7: 46095 | B7: Tax | C7: Road tax (VED) 12 mo | D7: DVLA | E7: 430 | F7: 76632 | G7: Direct debit | H7: Verify actual payment method/date | I7: =SUM($E$5:E7) -> 2647.14 | K7: Repair
A8: 46095 | B8: Tools/Equipment | C8: Various tools and equipment | D8: Amazon, Euro Car Parts, Halfords | E8: 500 | F8: 76632 | G8: Credit card | H8: Battery maintainer, jump start kit, tyre inflator, scissor jack, fluids, phone holder, storage solution, FM transmitter, cleaning supplies, toolbox, replacement fuses, small bits | I8: =SUM($E$5:E8) -> 3147.14 | K8: Parts
A9: 46132 | B9: Parking | C9: Monthly parking fee | D9: Surbiton Station Car Park | E9: 440 | F9: 77000 | G9: Credit card | H9: Ring go parking fee to date | I9: =SUM($E$5:E9) -> 3587.14
A10: 46154 | B10: Service | C10: Major service, checks and small repairs | D10: K & P Motors Kingston | E10: 570 | F10: 78840 | G10: Credit card | H10: General check, some repairs, assesment | I10: =SUM($E$5:E10) -> 4157.14 | K10: Insurance
A11: 46154 | B11: Parts | C11: Garage repairs | D11: eBay | E11: 13.99 | F11: 78840 | G11: Credit card | H11: Coolant tank replacement | I11: =SUM($E$5:E11) -> 4171.13 | K11: Tax
A12: 46157 | B12: Fuel | C12: Fuel | D12: Esso | E12: 453.17 | F12: 79031 | G12: Credit card | H12: Fuel to date | I12: =SUM($E$5:E12) -> 4624.3
A13: 46162 | B13: Wash | C13: Wash | D13: Power Foam | E13: 24 | F13: 79031 | G13: Credit card | H13: Wash to date | I13: =SUM($E$5:E13) -> 4648.3 | K13: MOT
A14: 46165 | B14: Fuel | C14: Fuel | D14: Esso | E14: 67.61 | F14: 79316 | G14: Credit card | I14: =SUM($E$5:E14) -> 4715.91 | K14: Wash
A15: 46179 | B15: Fuel | C15: Fuel | D15: Texaco Cotswolds | E15: 73.55 | F15: 79911 | G15: Credit card | I15: =SUM($E$5:E15) -> 4789.46 | K15: Parking
A16: 46187 | B16: Fuel | C16: Fuel | D16: Random Peak District station | E16: 72.52 | F16: 80197 | G16: Credit card | I16: =SUM($E$5:E16) -> 4861.98 | K16: Tools/Equipment
A17: 46192 | B17: Tools/Equipment | C17: Various tools and equipment | D17: Amazon | E17: 131.88 | F17: 80400 | G17: Credit card | H17: Sockets, wrenches, axle stands, toolbox | I17: =SUM($E$5:E17) -> 4993.86 | K17: Breakdown
A18: 46192 | B18: Parts | C18: Replacement parts | D18: JGS4x4, eBay | E18: 20 | F18: 80400 | G18: Credit card | H18: Led number plate light replacement and reverse lights switch | I18: =SUM($E$5:E18) -> 5013.86 | K18: Purchase
A19: 46196 | B19: Fuel | C19: Fuel | D19: Esso | E19: 58.85 | F19: 80449 | G19: Credit card | I19: =SUM($E$5:E19) -> 5072.71 | K19: Misc
A20: 46203 | B20: Wash | C20: Wash | D20: Power Foam | E20: 16 | F20: 80450 | G20: Credit card | I20: =SUM($E$5:E20) -> 5088.71
A21: 46211 | B21: MOT | C21: MOT | D21: K & P Motors Kingston | E21: 58 | F21: 80705 | G21: Credit card | H21: MOT Test - Passed | I21: =SUM($E$5:E21) -> 5146.71
I22: =SUM($E$5:E22) -> 5146.71
I23: =SUM($E$5:E23) -> 5146.71
I24: =SUM($E$5:E24) -> 5146.71
I25: =SUM($E$5:E25) -> 5146.71
I26: =SUM($E$5:E26) -> 5146.71
I27: =SUM($E$5:E27) -> 5146.71
I28: =SUM($E$5:E28) -> 5146.71
I29: =SUM($E$5:E29) -> 5146.71
I30: =SUM($E$5:E30) -> 5146.71
I31: =SUM($E$5:E31) -> 5146.71
I32: =SUM($E$5:E32) -> 5146.71
I33: =SUM($E$5:E33) -> 5146.71
... I41: =SUM($E$5:E41) -> 5146.71
I42: =SUM($E$5:E53) -> 5146.71
I43: =SUM($E$5:E43) -> 5146.71
I44: =SUM($E$5:E44) -> 5146.71
I45: =SUM($E$5:E45) -> 5146.71
I46: =SUM($E$5:E46) -> 5146.71
I47: =SUM($E$5:E47) -> 5146.71
I48: =SUM($E$5:E48) -> 5146.71
...

Sheet Fuel Log
A1: Fuel Log & MPG Tracking
A2: Fill in date, mileage, litres, price/L. Total, miles since last, and MPG calculate automatically.
A3: Tip: mirror each entry to Expenses Log under Category = Fuel.
A5: Date | B5: Mileage | C5: Litres | D5: Price/L (£) | E5: Total (£) | F5: Miles since last | G5: MPG (UK) | H5: L/100 KM (EU) | I5: Station | J5: Full tank | K5: Half | L5: Quarter
A6: 46130 | B6: 77537 | C6: 62 | D6: 1.589 | E6: =IF(OR(C6="",D6=""),"",C6*D6) -> 98.518 | F6: =IF(B6="","",B6-77203) -> 334 | G6: =IF(OR(C6="",F6="",C6=0),"",F6*4.54609/C6) -> 24.490227 | H6: =IF(G6="","",282.481/G6) -> 11.534438 | I6: - | J6: =IF(G6="","",ROUND(G6*(61/4.54609),0)) -> 329 | K6: =IF(G6="","",J6/2) -> 164.5 | L6: =IF(G6="","",J6/4) -> 82.25
A7: 46130 | B7: 77770 | C7: 36.78 | D7: 1.589 | E7: =IF(OR(C7="",D7=""),"",C7*D7) -> 58.44342 | F7: =IF(B7="","",B7-IFERROR(LOOKUP(2,1/(B$6:B6<>""),B$6:B6),76632)) -> 233 | G7: =IF(OR(C7="",F7="",C7=0),"",F7*4.54609/C7) -> 28.799319 | H7: =IF(G7="","",282.481/G7) -> 9.8085998 | I7: - | J7: =IF(G7="","",ROUND(G7*(61/4.54609),0)) -> 386 | K7: =IF(G7="","",J7/2) -> 193 | L7: =IF(G7="","",J7/4) -> 96.5
A8: 46133 | B8: 78079 | C8: 45.81 | D8: 1.569 | E8: =IF(OR(C8="",D8=""),"",C8*D8) -> 71.87589 | F8: =IF(B8="","",B8-IFERROR(LOOKUP(2,1/(B$6:B7<>""),B$6:B7),76632)) -> 309 | G8: =IF(OR(C8="",F8="",C8=0),"",F8*4.54609/C8) -> 30.664523 | H8: =IF(G8="","",282.481/G8) -> 9.2119808 | I8: Esso Express, Surbiton | J8: =IF(G8="","",ROUND(G8*(61/4.54609),0)) -> 411 | K8: =IF(G8="","",J8/2) -> 205.5 | L8: =IF(G8="","",J8/4) -> 102.75
A9: 46143 | B9: 78403 | C9: 45.81 | D9: 1.569 | E9: =IF(OR(C9="",D9=""),"",C9*D9) -> 71.87589 | F9: =IF(B9="","",B9-IFERROR(LOOKUP(2,1/(B$6:B8<>""),B$6:B8),76632)) -> 324 | G9: =IF(OR(C9="",F9="",C9=0),"",F9*4.54609/C9) -> 32.153092 | H9: =IF(G9="","",282.481/G9) -> 8.7855002 | J9: =IF(G9="","",ROUND(G9*(61/4.54609),0)) -> 431 | K9: =IF(G9="","",J9/2) -> 215.5 | L9: =IF(G9="","",J9/4) -> 107.75
A10: 46145 | B10: 78513 | C10: 18.74 | D10: 1.575 | E10: =IF(OR(C10="",D10=""),"",C10*D10) -> 29.5155 | F10: =IF(B10="","",B10-IFERROR(LOOKUP(2,1/(B$6:B9<>""),B$6:B9),76632)) -> 110 | G10: =IF(OR(C10="",F10="",C10=0),"",F10*4.54609/C10) -> 26.684626 | H10: =IF(G10="","",282.481/G10) -> 10.585908 | I10: Esso Express, Surbiton | J10: =IF(G10="","",ROUND(G10*(61/4.54609),0)) -> 358 | K10: =IF(G10="","",J10/2) -> 179 | L10: =IF(G10="","",J10/4) -> 89.5
A11: 46155 | B11: 78846 | C11: 50.65 | D11: 1.579 | E11: =IF(OR(C11="",D11=""),"",C11*D11) -> 79.97635 | F11: =IF(B11="","",B11-IFERROR(LOOKUP(2,1/(B$6:B10<>""),B$6:B10),76632)) -> 333 | G11: =IF(OR(C11="",F11="",C11=0),"",F11*4.54609/C11) -> 29.88841 | H11: =IF(G11="","",282.481/G11) -> 9.4511886 | I11: Esso Express, Surbiton | J11: =IF(G11="","",ROUND(G11*(61/4.54609),0)) -> 401 | K11: =IF(G11="","",J11/2) -> 200.5 | L11: =IF(G11="","",J11/4) -> 100.25
A12: 46159 | B12: 79031 | C12: 27.21 | D12: 1.579 | E12: =IF(OR(C12="",D12=""),"",C12*D12) -> 42.96459 | F12: =IF(B12="","",B12-IFERROR(LOOKUP(2,1/(B$6:B11<>""),B$6:B11),76632)) -> 185 | G12: =IF(OR(C12="",F12="",C12=0),"",F12*4.54609/C12) -> 30.908734 | H12: =IF(G12="","",282.481/G12) -> 9.1391967 | I12: Esso, Avon (Bath) | J12: =IF(G12="","",ROUND(G12*(61/4.54609),0)) -> 415 | K12: =IF(G12="","",J12/2) -> 207.5 | L12: =IF(G12="","",J12/4) -> 103.75
A13: 46165 | B13: 79316 | C13: 42.82 | D13: 1.579 | E13: =IF(OR(C13="",D13=""),"",C13*D13) -> 67.61278 | F13: =IF(B13="","",B13-IFERROR(LOOKUP(2,1/(B$6:B12<>""),B$6:B12),76632)) -> 285 | G13: =IF(OR(C13="",F13="",C13=0),"",F13*4.54609/C13) -> 30.257722 | H13: =IF(G13="","",282.481/G13) -> 9.3358317 | I13: Esso Express, Surbiton | J13: =IF(G13="","",ROUND(G13*(61/4.54609),0)) -> 406 | K13: =IF(G13="","",J13/2) -> 203 | L13: =IF(G13="","",J13/4) -> 101.5
A14: 46172 | B14: 79630 | C14: 47.32 | D14: 1.659 | E14: =IF(OR(C14="",D14=""),"",C14*D14) -> 78.50388 | F14: =IF(B14="","",B14-IFERROR(LOOKUP(2,1/(B$6:B13<>""),B$6:B13),76632)) -> 314 | G14: =IF(OR(C14="",F14="",C14=0),"",F14*4.54609/C14) -> 30.166362 | H14: =IF(G14="","",282.481/G14) -> 9.3641056 | I14: Shell, Liphook, A3 | J14: =IF(G14="","",ROUND(G14*(61/4.54609),0)) -> 405 | K14: =IF(G14="","",J14/2) -> 202.5 | L14: =IF(G14="","",J14/4) -> 101.25
A15: 46179 | B15: 79911 | C15: 45.43 | D15: 1.62 | E15: =IF(OR(C15="",D15=""),"",C15*D15) -> 73.5966 | F15: =IF(B15="","",B15-IFERROR(LOOKUP(2,1/(B$6:B14<>""),B$6:B14),76632)) -> 281 | G15: =IF(OR(C15="",F15="",C15=0),"",F15*4.54609/C15) -> 28.119113 | H15: =IF(G15="","",282.481/G15) -> 10.045872 | I15: Texaco North Chipperring | J15: =IF(G15="","",ROUND(G15*(61/4.54609),0)) -> 377 | K15: =IF(G15="","",J15/2) -> 188.5 | L15: =IF(G15="","",J15/4) -> 94.25
A16: 46187 | B16: 80197 | C16: 48.38 | D16: 1.499 | E16: =IF(OR(C16="",D16=""),"",C16*D16) -> 72.52162 | F16: =IF(B16="","",B16-IFERROR(LOOKUP(2,1/(B$6:B15<>""),B$6:B15),76632)) -> 286 | G16: =IF(OR(C16="",F16="",C16=0),"",F16*4.54609/C16) -> 26.874364 | H16: =IF(G16="","",282.481/G16) -> 10.51117 | I16: Random Peak District station | J16: =IF(G16="","",ROUND(G16*(61/4.54609),0)) -> 361 | K16: =IF(G16="","",J16/2) -> 180.5 | L16: =IF(G16="","",J16/4) -> 90.25
A17: 46196 | B17: 80449 | C17: 38.49 | D17: 1.529 | E17: =IF(OR(C17="",D17=""),"",C17*D17) -> 58.85121 | F17: =IF(B17="","",B17-IFERROR(LOOKUP(2,1/(B$6:B16<>""),B$6:B16),76632)) -> 252 | G17: =IF(OR(C17="",F17="",C17=0),"",F17*4.54609/C17) -> 29.763956 | H17: =IF(G17="","",282.481/G17) -> 9.4907074 | I17: Esso Hampton Court | J17: =IF(G17="","",ROUND(G17*(61/4.54609),0)) -> 399 | K17: =IF(G17="","",J17/2) -> 199.5 | L17: =IF(G17="","",J17/4) -> 99.75
A18: 46213 | B18: 80712 | C18: 47.03 | D18: 1.799 | E18: =IF(OR(C18="",D18=""),"",C18*D18) -> 84.60697 | F18: =IF(B18="","",B18-IFERROR(LOOKUP(2,1/(B$6:B17<>""),B$6:B17),76632)) -> 263 | G18: =IF(OR(C18="",F18="",C18=0),"",F18*4.54609/C18) -> 25.422532 | H18: =IF(G18="","",282.481/G18) -> 11.111442 | I18: Shell Kingston VPower | J18: =IF(G18="","",ROUND(G18*(61/4.54609),0)) -> 341 | K18: =IF(G18="","",J18/2) -> 170.5 | L18: =IF(G18="","",J18/4) -> 85.25
E19: =IF(OR(C19="",D19=""),"",C19*D19) | F19: =IF(B19="","",B19-IFERROR(LOOKUP(2,1/(B$6:B18<>""),B$6:B18),76632)) | G19: =IF(OR(C19="",F19="",C19=0),"",F19*4.54609/C19) | H19: =IF(G19="","",282.481/G19) | J19: =IF(G19="","",ROUND(G19*(61/4.54609),0)) | K19: =IF(G19="","",J19/2) | L19: =IF(G19="","",J19/4)
E20: =IF(OR(C20="",D20=""),"",C20*D20) | F20: =IF(B20="","",B20-IFERROR(LOOKUP(2,1/(B$6:B19<>""),B$6:B19),76632)) | G20: =IF(OR(C20="",F20="",C20=0),"",F20*4.54609/C20) | H20: =IF(G20="","",282.481/G20) | J20: =IF(G20="","",ROUND(G20*(61/4.54609),0)) | K20: =IF(G20="","",J20/2) | L20: =IF(G20="","",J20/4)
E21: =IF(OR(C21="",D21=""),"",C21*D21) | F21: =IF(B21="","",B21-IFERROR(LOOKUP(2,1/(B$6:B20<>""),B$6:B20),76632)) | G21: =IF(OR(C21="",F21="",C21=0),"",F21*4.54609/C21) | H21: =IF(G21="","",282.481/G21) | J21: =IF(G21="","",ROUND(G21*(61/4.54609),0)) | K21: =IF(G21="","",J21/2) | L21: =IF(G21="","",J21/4)
E22: =IF(OR(C22="",D22=""),"",C22*D22) | F22: =IF(B22="","",B22-IFERROR(LOOKUP(2,1/(B$6:B21<>""),B$6:B21),76632)) | G22: =IF(OR(C22="",F22="",C22=0),"",F22*4.54609/C22) | H22: =IF(G22="","",282.481/G22) | J22: =IF(G22="","",ROUND(G22*(61/4.54609),0)) | K22: =IF(G22="","",J22/2) | L22: =IF(G22="","",J22/4)
E23: =IF(OR(C23="",D23=""),"",C23*D23) | F23: =IF(B23="","",B23-IFERROR(LOOKUP(2,1/(B$6:B22<>""),B$6:B22),76632)) | G23: =IF(OR(C23="",F23="",C23=0),"",F23*4.54609/C23) | H23: =IF(G23="","",282.481/G23) | J23: =IF(G23="","",ROUND(G23*(61/4.54609),0)) | K23: =IF(G23="","",J23/2) | L23: =IF(G23="","",J23/4)
E24: =IF(OR(C24="",D24=""),"",C24*D24) | F24: =IF(B24="","",B24-IFERROR(LOOKUP(2,1/(B$6:B23<>""),B$6:B23),76632)) | G24: =IF(OR(C24="",F24="",C24=0),"",F24*4.54609/C24) | H24: =IF(G24="","",282.481/G24) | J24: =IF(G24="","",ROUND(G24*(61/4.54609),0)) | K24: =IF(G24="","",J24/2) | L24: =IF(G24="","",J24/4)
E25: =IF(OR(C25="",D25=""),"",C25*D25) | F25: =IF(B25="","",B25-IFERROR(LOOKUP(2,1/(B$6:B24<>""),B$6:B24),76632)) | G25: =IF(OR(C25="",F25="",C25=0),"",F25*4.54609/C25) | H25: =IF(G25="","",282.481/G25) | J25: =IF(G25="","",ROUND(G25*(61/4.54609),0)) | K25: =IF(G25="","",J25/2) | L25: =IF(G25="","",J25/4)
E26: =IF(OR(C26="",D26=""),"",C26*D26) | F26: =IF(B26="","",B26-IFERROR(LOOKUP(2,1/(B$6:B25<>""),B$6:B25),76632)) | G26: =IF(OR(C26="",F26="",C26=0),"",F26*4.54609/C26) | H26: =IF(G26="","",282.481/G26) | J26: =IF(G26="","",ROUND(G26*(61/4.54609),0)) | K26: =IF(G26="","",J26/2) | L26: =IF(G26="","",J26/4)
E27: =IF(OR(C27="",D27=""),"",C27*D27) | F27: =IF(B27="","",B27-IFERROR(LOOKUP(2,1/(B$6:B26<>""),B$6:B26),76632)) | G27: =IF(OR(C27="",F27="",C27=0),"",F27*4.54609/C27) | H27: =IF(G27="","",282.481/G27) | J27: =IF(G27="","",ROUND(G27*(61/4.54609),0)) | K27: =IF(G27="","",J27/2) | L27: =IF(G27="","",J27/4)
E28: =IF(OR(C28="",D28=""),"",C28*D28) | F28: =IF(B28="","",B28-IFERROR(LOOKUP(2,1/(B$6:B27<>""),B$6:B27),76632)) | G28: =IF(OR(C28="",F28="",C28=0),"",F28*4.54609/C28) | H28: =IF(G28="","",282.481/G28) | J28: =IF(G28="","",ROUND(G28*(61/4.54609),0)) | K28: =IF(G28="","",J28/2) | L28: =IF(G28="","",J28/4)
E29: =IF(OR(C29="",D29=""),"",C29*D29) | F29: =IF(B29="","",B29-IFERROR(LOOKUP(2,1/(B$6:B28<>""),B$6:B28),76632)) | G29: =IF(OR(C29="",F29="",C29=0),"",F29*4.54609/C29) | H29: =IF(G29="","",282.481/G29) | J29: =IF(G29="","",ROUND(G29*(61/4.54609),0)) | K29: =IF(G29="","",J29/2) | L29: =IF(G29="","",J29/4)
E30: =IF(OR(C30="",D30=""),"",C30*D30) | F30: =IF(B30="","",B30-IFERROR(LOOKUP(2,1/(B$6:B29<>""),B$6:B29),76632)) | G30: =IF(OR(C30="",F30="",C30=0),"",F30*4.54609/C30) | H30: =IF(G30="","",282.481/G30) | J30: =IF(G30="","",ROUND(G30*(61/4.54609),0)) | K30: =IF(G30="","",J30/2) | L30: =IF(G30="","",J30/4)
... E200: =IF(OR(C200="",D200=""),"",C200*D200) | F200: =IF(B200="","",B200-IFERROR(LOOKUP(2,1/(B$6:B199<>""),B$6:B199),76632)) | G200: =IF(OR(C200="",F200="",C200=0),"",F200*4.54609/C200) | H200: =IF(G200="","",282.481/G200) | J200: =IF(G200="","",ROUND(G200*(61/4.54609),0)) | K200: =IF(G200="","",J200/2) | L200: =IF(G200="","",J200/4)
G201: =IF(OR(C201="",F201="",C201=0),"",F201*4.54609/C201) | H201: =IF(G201="","",282.481/G201) | J201: =IF(G201="","",ROUND(G201*(61/4.54609),0)) | K201: =IF(G201="","",J201/2) | L201: =IF(G201="","",J201/4)
A202: SUMMARY | C202: =IFERROR(SUM(C6:C200),0) -> 556.47 | E202: =IFERROR(SUM(E6:E200),0) -> 888.8627 | F202: =IFERROR(SUM(F6:F200),0) -> 3509 | G202: =IF(OR(C202="",F202="",C202=0),"",F202*4.54609/C202) -> 28.666828 | H202: =IF(G202="","",282.481/G202) -> 9.8539329

Sheet Service History
A1: Service & Maintenance History
A2: Permanent service record. Keep the Next Due (miles/date) columns filled so Dashboard can flag upcoming services.
A4: Date | B4: Mileage | C4: Type | D4: Garage | E4: Work Done | F4: Parts Replaced | G4: Cost (£) | H4: Next Due (miles) | I4: Next Due (date) | J4: Notes
A5: 45855 | B5: 76632 | C5: MOT Test | D5: Unknown (pre-ownership) | E5: MOT test - Passed | I5: 46240 | J5: Advisories: oil leak (minor, recurring since 2024 - likely cam seals); brake pipe corrosion both sides (recurring since 2024, advisory not failure); central stop lamp not working.
A6: 46095 | B6: 76632 | C6: Pre-purchase check | D6: Self (at viewing) | E6: Oil cap underside clean, coolant clean, no head gasket warning signs. VCU tested on tight turns - no shuddering. | J6: Purchase inspection. K-series HG history unknown per seller.
A7: 46101 | B7: 76700 | C7: Hand-brake adjustement | D7: Self (parking lot) | E7: Adjusted the handbrake to lock between 4th and 5th notch, but have not lifter the car up | J7: Needs review in the garage
A8: 46154 | B8: 78840 | C8: Major service | D8: K & P Motors Kingston | E8: Full service: oil + filter, air filter, fuel filter, spark plugs. Inspect brake pipe corrosion advisories. Inspect cam seals (oil leak source). AC check ahead of summer. Head gasket assessment. | G8: 511.8 | H8: 87500 | I8: 46519 | J8: A/C Recharge Head gasket leak test Coolant pressure test Stop light bulb Major Service Passenger side rear Number plate bulb Reverse light bulb replacement Driver side rear stop light bulb
A9: 46200 | B9: 83000 | C9: Reverse gear switch replacement | D9: Self (friend's driveway) | E9: Replaced reverse lights switch, number plate light to a LED one, fixed connectors and cables, wrapped connectors in the engine bay in electrical tape. | J9: Reverse lights fixed Hill Descent Control fixed Number plate light fixed Parking sensor now operational
A10: 46211 | B10: 80705 | C10: MOT Test | D10: K & P Motors Kingston | E10: MOT test - Passed | G10: 58 | I10: 46576 | J10: Advisories: headlamps lens slightly defective - both (repair asap), rear tyres slightly cracking (monitor)
F34: TOTAL SPENT | G34: =SUMIF(G5:G8,">0") -> 511.8

Sheet DIY To-Do
A1: DIY Tasks
A2: Things you can tackle yourself. Set Status to Open / In Progress / Done. Priority: High / Medium / Low.
A4: Priority | B4: Task | C4: Description | D4: Est. Cost (£) | E4: Status | F4: Target Date | G4: Completed Date | H4: Notes
A5: High | B5: Replace fuel cap | C5: Current temporary cap is a broken flexi cap (plastic locking tabs snapped). Order proper replacement. | D5: 12 | E5: Done | F5: 46142 | G5: 46111 | H5: Search "Freelander 1 fuel cap" on eBay/Amazon - expect £5-15.
A6: High | B6: Order NOCO Genius5 charger/maintainer | C6: Battery maintainer for extended parked periods. ~£65-80. | D6: 75 | E6: Done | F6: 46142 | G6: 46111 | H6: Amazon.
A7: High | B7: Order NOCO Boost GB40 jump starter | C7: Portable jump pack for emergencies. ~£80-100. | D7: 90 | E7: Done | F7: 46142 | G7: 46111 | H7: Amazon.
A8: Medium | B8: Investigate instrument cluster backlight | C8: Speedometer/instrument cluster backlight not working. Check fuse first (likely labelled in handbook), then consider pulling cluster for bulb replacement - can be DIY but fiddly. | D8: 15 | E8: Done | F8: 46173 | G8: 46111 | H8: If too fiddly, leave for WCarey. Estimated £30-50 at garage.
A9: Low | B9: Check all exterior lights weekly | C9: Walk-around check: headlights (main + dip), indicators (front/rear/side), brake lights (all 3), reversing, number plate, fog lights. | D9: 0 | E9: Done | H9: Ongoing - log in Regular Checks.
A10: Low | B10: Clean leather seats | C10: Interior is cream leather - needs leather cleaner + conditioner. | D10: 20 | E10: Open | F10: 46173 | H10: Buy Gliptone Liquid Leather or similar.
A11: Low | B11: Top up windscreen washer fluid | C11: Check reservoir and top up with screenwash (concentrated + water). | D11: 5 | E11: Done | F11: 46142 | H11: Check mix ratio for summer/winter protection.
A12: Low | B12: Photograph current condition for records | C12: Full photoset of exterior, interior, wheels, under bonnet, underneath. Useful for insurance claims and before/after repairs. | D12: 0 | E12: Open | F12: 46173 | H12: Store with other vehicle documents.
A13: Low | B13: Clean brake pipes | C13: Clean and protect brake pipes | D13: 50 | E13: Open | F13: 46203 | H13: Need to wire brush and clean the brake pipes, then grease/paint for protection
A14: Medium | B14: Petrol additive | C14: use AR640 from Dug to clean the fuel system | D14: 20 | E14: Open | F14: 46196 | H14: Buy more so can do it again in a few months
A15: Medium | B15: Replace gear shift knob and gaiter | C15: Old leather is done, cracked gaiter, knob is a mess | D15: 120 | E15: Open | F15: 46234 | H15: Find parts and replace
B19: Total estimated cost (Open + In Progress) | D19: =SUMIFS(D5:D18,E5:E18,"Open")+SUMIFS(D5:D18,E5:E18,"In Progress") -> 210

Sheet Workshop To-Do
A1: Workshop Tasks (WCarey & others)
A2: Jobs for the garage. Bundle these into service visits to save on labour.
A4: Priority | B4: Task | C4: Description | D4: Est. Cost (£) | E4: Status | F4: Target Service | G4: Completed Date | H4: Garage | I4: Notes
A5: High | B5: Full service | C5: Engine oil + filter, air filter, fuel filter, spark plugs. Baseline service post-purchase. | D5: 250 | E5: Done | F5: 46157 | G5: 46155 | H5: K & P Motors Kingston | I5: Establish baseline. Get itemised quote. May 2026 booking.
A6: High | B6: Head gasket assessment | C6: Compression test and/or sniff test to detect combustion gases in coolant. K-series is notorious - worth a preventative check early in ownership. | D6: 40 | E6: Done | F6: 46157 | G6: 46155 | H6: K & P Motors Kingston | I6: HG test passed per K & P tests, coolant CO2 check passed
A7: High | B7: Inspect cam seals (oil leak) | C7: Advisory recurring since 2024 MOT. Confirm source of leak - likely cam seals per friend. Reseal if confirmed. | D7: 80 | E7: Done | F7: 46157 | G7: 46155 | H7: K & P Motors Kingston | I7: Typical/cheap fix per front cam shaft seal leaking slightly
A8: High | B8: Inspect brake pipe corrosion (advisory) | C8: Both sides - advisory since 2024. Needs proper inspection - if any are perished, replace before next MOT (Aug 2026). | D8: 150 | E8: Done | F8: 46157 | G8: 46155 | H8: K & P Motors Kingston | I8: If still only surface corrosion, wire brush + anti-rust treatment may buy time. Replace if pitted.
A9: Medium | B9: AC system check | C9: Ahead of summer - check refrigerant charge, condenser, cabin filter. Re-gas if needed. | D9: 80 | E9: Done | F9: 46157 | G9: 46155 | H9: K & P Motors Kingston | I9: AC Compressor not working
A10: Medium | B10: VCU condition check | C10: Viscous Coupling Unit health check. Known weak point on Freelander 1 - can seize and destroy IRD/rear diff. | D10: 30 | E10: Done | F10: 46157 | G10: 46155 | H10: K & P Motors Kingston | I10: Ask for their assessment. Replacement VCU ~£150-250 + labour.
A11: Low | B11: Check coolant condition and top-up with OAT | C11: K-series needs OAT coolant (red/pink) - verify current fluid and flush/refill if wrong type or old. | D11: 40 | E11: Done | F11: 46157 | G11: 46155 | H11: K & P Motors Kingston | I11: Critical for head gasket longevity.
A12: Low | B12: Check brake fluid condition | C12: Brake fluid absorbs moisture over time. Test with moisture meter, flush if needed. | D12: 50 | E12: Done | F12: 46157 | G12: 46155 | H12: K & P Motors Kingston | I12: Bundle with service visit.
A13: High | B13: Electrical fixes | C13: Bulbs replaced, but still not working. Central brake light, two reverse indicator lights, number plate lights, AC Compressor busted or not working | D13: 200 | E13: Done | F13: 46172 | G13: 46186 | H13: K & P Motors Kingston
A14: Medium | B14: Back window sensor/seals/mechanism | C14: The window close sensor is forcing it to go down, mechanism or sensor, or seals, or everything together needs a reset or fixes | D14: 150 | E14: Open | F14: 46203
B34: Total estimated cost (Open + Scheduled) | D34: =SUMIFS(D5:D30,E5:E30,"Open")+SUMIFS(D5:D30,E5:E30,"Scheduled") -> 150

Sheet Regular Checks
A1: Regular Inspection Checks
A2: Update "Last Done" and the sheet tells you when the next one is due and if you are overdue.
A4: Check | B4: Cadence | C4: Interval (days) | D4: Last Done | E4: Next Due | F4: Status | G4: Last Result / Notes
A5: Oil filler cap underside (mayo/creamy residue check) | B5: Weekly | C5: 7 | D5: 46191 | E5: =IF(D5="","—",D5+C5) -> 46198 | F5: =IF(D5="","Not logged",IF(TODAY()>E5,"Overdue",IF(E5-TODAY()<=7,"Due Soon","OK"))) -> Overdue | G5: No residue = healthy. Any creamy white/yellow = possible head gasket issue.
A6: Coolant reservoir colour & level | B6: Weekly | C6: 7 | D6: 46191 | E6: =IF(D6="","—",D6+C6) -> 46198 | F6: =IF(D6="","Not logged",IF(TODAY()>E6,"Overdue",IF(E6-TODAY()<=7,"Due Soon","OK"))) -> Overdue | G6: Should be clean red/pink (OAT). Brown/oily/milky = head gasket concern.
A7: Windscreen washer fluid | B7: Weekly | C7: 7 | D7: 46191 | E7: =IF(D7="","—",D7+C7) -> 46198 | F7: =IF(D7="","Not logged",IF(TODAY()>E7,"Overdue",IF(E7-TODAY()<=7,"Due Soon","OK"))) -> Overdue | G7: Top up with screenwash mix.
A8: Visual tyre check (cuts, bulges, unusual wear) | B8: Weekly | C8: 7 | D8: 46191 | E8: =IF(D8="","—",D8+C8) -> 46198 | F8: =IF(D8="","Not logged",IF(TODAY()>E8,"Overdue",IF(E8-TODAY()<=7,"Due Soon","OK"))) -> Overdue | G8: Walk-around visual only. Proper pressure/tread check is monthly/quarterly.
A9: Dashboard warning lights (on start) | B9: Weekly | C9: 7 | D9: 46191 | E9: =IF(D9="","—",D9+C9) -> 46198 | F9: =IF(D9="","Not logged",IF(TODAY()>E9,"Overdue",IF(E9-TODAY()<=7,"Due Soon","OK"))) -> Overdue | G9: Mental note on startup - any warning light that stays on post-start needs action.
A10: All exterior lights walk-around | B10: Monthly | C10: 30 | D10: 46191 | E10: =IF(D10="","—",D10+C10) -> 46221 | F10: =IF(D10="","Not logged",IF(TODAY()>E10,"Overdue",IF(E10-TODAY()<=7,"Due Soon","OK"))) -> Due Soon | G10: Head, dip, main beam, indicators (F/R/side), brake (all 3 incl central), reversing, number plate, fog.
A11: Engine oil level (dipstick) | B11: Monthly | C11: 30 | D11: 46183 | E11: =IF(D11="","—",D11+C11) -> 46213 | F11: =IF(D11="","Not logged",IF(TODAY()>E11,"Overdue",IF(E11-TODAY()<=7,"Due Soon","OK"))) -> Overdue | G11: Cold engine, level surface, wipe and re-dip. Between MIN and MAX.
A12: Tyre pressures (all 4 + spare) | B12: Monthly | C12: 30 | D12: 46174 | E12: =IF(D12="","—",D12+C12) -> 46204 | F12: =IF(D12="","Not logged",IF(TODAY()>E12,"Overdue",IF(E12-TODAY()<=7,"Due Soon","OK"))) -> Overdue | G12: Cold tyres. Log values in Tyre Log sheet. Include spare.
A13: Battery terminals (corrosion check) | B13: Monthly | C13: 30 | D13: 46191 | E13: =IF(D13="","—",D13+C13) -> 46221 | F13: =IF(D13="","Not logged",IF(TODAY()>E13,"Overdue",IF(E13-TODAY()<=7,"Due Soon","OK"))) -> Due Soon | G13: Check for green/white deposits. Clean if needed.
A14: Under-bonnet visual scan | B14: Monthly | C14: 30 | D14: 46191 | E14: =IF(D14="","—",D14+C14) -> 46221 | F14: =IF(D14="","Not logged",IF(TODAY()>E14,"Overdue",IF(E14-TODAY()<=7,"Due Soon","OK"))) -> Due Soon | G14: Look for new oil spots, coolant drips, loose hoses, anything unusual.
A15: Tread depth (proper gauge) | B15: Quarterly | C15: 90 | D15: 46155 | E15: =IF(D15="","—",D15+C15) -> 46245 | F15: =IF(D15="","Not logged",IF(TODAY()>E15,"Overdue",IF(E15-TODAY()<=7,"Due Soon","OK"))) -> OK | G15: Log in Tyre Log. Minimum legal 1.6 mm - replace at 3 mm.
A16: Brake fluid level | B16: Quarterly | C16: 90 | D16: 46155 | E16: =IF(D16="","—",D16+C16) -> 46245 | F16: =IF(D16="","Not logged",IF(TODAY()>E16,"Overdue",IF(E16-TODAY()<=7,"Due Soon","OK"))) -> OK | G16: Check reservoir - between MIN and MAX. Dark brown fluid = flush due.
... A20: Door/boot seals & hinges lubrication | B20: Every 6 months | C20: 180 | D20: 46155 | E20: =IF(D20="","—",D20+C20) -> 46335 | F20: =IF(D20="","Not logged",IF(TODAY()>E20,"Overdue",IF(E20-TODAY()<=7,"Due Soon","OK"))) -> OK | G20: Silicone spray on rubber seals, white lithium grease on hinges/latches.
A21: Spare tyre pressure | B21: Every 6 months | C21: 180 | E21: =IF(D21="","—",D21+C21) -> — | F21: =IF(D21="","Not logged",IF(TODAY()>E21,"Overdue",IF(E21-TODAY()<=7,"Due Soon","OK"))) -> Not logged
A22: Headlight alignment (visual) | B22: Yearly | C22: 365 | D22: 46155 | E22: =IF(D22="","—",D22+C22) -> 46520 | F22: =IF(D22="","Not logged",IF(TODAY()>E22,"Overdue",IF(E22-TODAY()<=7,"Due Soon","OK"))) -> OK | G22: Park 5m from a wall, compare left/right beam heights.

Sheet Wash Log
A1: Wash Log
A2: Target cadence: every 3-4 weeks minimum (more often in winter road-salt season).
A4: Date | B4: Location | C4: Type | D4: Cost (£) | E4: Mileage | F4: Notes | H4: Wash locations
A5: 46124 | B5: Power Foam - Shannon Corner | C5: Foam wash, full | D5: 10 | E5: 77000 | H5: Power Foam - Shannon Corner, New Malden KT3 6HF (24 hrs, closest)
A6: 46162 | B6: Power Foam - Shannon Corner | C6: Foam wash, full | D6: 14 | E6: 79000 | H6: BP Car Wash - Ewell KT17 (enclosed bay, 3.8/5, 30% off with BP reward)
A7: 46203 | B7: Power Foam - Shannon Corner | C7: Foam wash, full | D7: 16 | E7: 80450 | H7: Shell Jet Wash - Cobham (good reviews, quieter, on route to WCarey)
H8: Home driveway (if available)

Sheet Tyre Log
A1: Tyre Pressure & Tread Log
A2: Log pressures (PSI, cold) and tread depths (mm) per corner. Note any uneven wear.
A3: Target: Front 26 PSI / Rear 30 PSI (normal load) — VERIFY from door jamb sticker.
A5: Date | B5: Mileage | C5: FL PSI | D5: FR PSI | E5: RL PSI | F5: RR PSI | G5: Spare PSI | H5: FL Tread (mm) | I5: FR Tread (mm) | J5: RL Tread (mm) | K5: RR Tread (mm) | L5: Location/Tool | M5: Notes
A6: 46123 | C6: 35 | D6: 35 | E6: 35 | F6: 35 | H6: 6 | I6: 6 | J6: 6 | K6: 6 | L6: Shannon Corner
A7: 46147 | C7: 35 | D7: 35 | E7: 35 | F7: 35 | H7: 6 | I7: 6 | J7: 6 | K7: 6 | L7: Surbiton Station Car Park
A8: 46165 | C8: 35 | D8: 35 | E8: 35 | F8: 35 | H8: 6 | I8: 6 | J8: 6 | K8: 6 | L8: Surbiton Station Car Park

Sheet Budget
A1: Annual Budget vs Actual
A2: Edit the yellow Annual Budget column. Actual pulls from Expenses Log automatically.
A3: YTD uses current calendar year. Period covered: {year}.
A5: Category | B5: Annual Budget (£) | C5: YTD Actual (£) | D5: Remaining (£) | E5: % Used | F5: Notes
A6: Fuel | B6: 4200 | C6: =SUMIFS('Expenses Log'!E:E,'Expenses Log'!A:A,">="&DATE(YEAR(TODAY()),1,1),'Expenses Log'!B:B,A6) -> 725.7 | D6: =B6-C6 -> 3474.3 | E6: =IFERROR(C6/B6,0) -> 0.17278571 | F6: Based on ~16,000 mi/yr @ 26 mpg @ £1.5/L
A7: Service | B7: 400 | C7: =SUMIFS('Expenses Log'!E:E,'Expenses Log'!A:A,">="&DATE(YEAR(TODAY()),1,1),'Expenses Log'!B:B,A7) -> 570 | D7: =B7-C7 -> -170 | E7: =IFERROR(C7/B7,0) -> 1.425 | F7: Full service at K & P + consumables
A8: Repair | B8: 300 | C8: =SUMIFS('Expenses Log'!E:E,'Expenses Log'!A:A,">="&DATE(YEAR(TODAY()),1,1),'Expenses Log'!B:B,A8) -> 0 | D8: =B8-C8 -> 300 | E8: =IFERROR(C8/B8,0) -> 0 | F8: Contingency for brake pipes, cam seals etc
A9: Parts | B9: 150 | C9: =SUMIFS('Expenses Log'!E:E,'Expenses Log'!A:A,">="&DATE(YEAR(TODAY()),1,1),'Expenses Log'!B:B,A9) -> 33.99 | D9: =B9-C9 -> 116.01 | E9: =IFERROR(C9/B9,0) -> 0.2266 | F9: DIY parts (fuel cap, bulbs, filters if DIY)
A10: Insurance | B10: 517.14 | C10: =SUMIFS('Expenses Log'!E:E,'Expenses Log'!A:A,">="&DATE(YEAR(TODAY()),1,1),'Expenses Log'!B:B,A10) -> 517.14 | D10: =B10-C10 -> 0 | E10: =IFERROR(C10/B10,0) -> 1 | F10: Admiral policy
A11: Tax | B11: 430 | C11: =SUMIFS('Expenses Log'!E:E,'Expenses Log'!A:A,">="&DATE(YEAR(TODAY()),1,1),'Expenses Log'!B:B,A11) -> 430 | D11: =B11-C11 -> 0 | E11: =IFERROR(C11/B11,0) -> 1 | F11: VED annual
A12: MOT | B12: 55 | C12: =SUMIFS('Expenses Log'!E:E,'Expenses Log'!A:A,">="&DATE(YEAR(TODAY()),1,1),'Expenses Log'!B:B,A12) -> 58 | D12: =B12-C12 -> -3 | E12: =IFERROR(C12/B12,0) -> 1.0545455 | F12: Next MOT due Aug 2026 (£54.85 max fee)
A13: Wash | B13: 120 | C13: =SUMIFS('Expenses Log'!E:E,'Expenses Log'!A:A,">="&DATE(YEAR(TODAY()),1,1),'Expenses Log'!B:B,A13) -> 40 | D13: =B13-C13 -> 80 | E13: =IFERROR(C13/B13,0) -> 0.33333333 | F13: ~£10/month
A14: Parking | B14: =200*6 -> 1200 | C14: =SUMIFS('Expenses Log'!E:E,'Expenses Log'!A:A,">="&DATE(YEAR(TODAY()),1,1),'Expenses Log'!B:B,A14) -> 440 | D14: =B14-C14 -> 760 | E14: =IFERROR(C14/B14,0) -> 0.36666667 | F14: Contingency
A15: Tools/Equipment | B15: 400 | C15: =SUMIFS('Expenses Log'!E:E,'Expenses Log'!A:A,">="&DATE(YEAR(TODAY()),1,1),'Expenses Log'!B:B,A15) -> 631.88 | D15: =B15-C15 -> -231.88 | E15: =IFERROR(C15/B15,0) -> 1.5797 | F15: NOCO charger + jump pack + basics + wrenches/spanners + toolboxes
A16: Breakdown | B16: 0 | C16: =SUMIFS('Expenses Log'!E:E,'Expenses Log'!A:A,">="&DATE(YEAR(TODAY()),1,1),'Expenses Log'!B:B,A16) -> 0 | D16: =B16-C16 -> 0 | E16: =IFERROR(C16/B16,0) -> 0 | F16: Included in Admiral - upgrade £95.45/yr for Home Start
A17: Misc | B17: 200 | C17: =SUMIFS('Expenses Log'!E:E,'Expenses Log'!A:A,">="&DATE(YEAR(TODAY()),1,1),'Expenses Log'!B:B,A17) -> 0 | D17: =B17-C17 -> 200 | E17: =IFERROR(C17/B17,0) -> 0 | F17: Buffer
A18: TOTAL | B18: =SUM(B6:B17) -> 7972.14 | C18: =SUM(C6:C17) -> 3446.71 | D18: =SUM(D6:D17) -> 4525.43 | E18: =IFERROR(C18/B18,0) -> 0.43234439
A21: Per-mile analysis
A22: Budgeted cost per mile | B22: =IFERROR(B18/16000,0) -> 0.49825875 | C22: Assumes 16,000 mi/year

Sheet Issues Watchlist
A1: Known Issues Watchlist
A2: Track deterioration of known weak points. Update Status and Observations over time.
A4: Issue | B4: Severity | C4: First Noted | D4: Last Checked | E4: Current Observation | F4: Action / Monitoring | G4: Est. Cost to Fix | H4: Status
A5: Check head gasket (K-series) | B5: Critical | C5: 46095 | D5: 46155 | E5: No signs at purchase: oil cap clean, coolant clean, no overheating. | F5: Stop driving immediately if temp gauge rises. Book HG replacement. Parts ~£70-100 if friend does labour, workshop £400-700+. | G5: 500 | H5: Resolved
A6: Oil leak (likely cam seals) | B6: Low | C6: 45474 | D6: 46155 | E6: Minor leak, recurring MOT advisory since 2024. Typical K-series per friend. | F6: Re-seal cam seals at service. ~£80 labour. | G6: 80 | H6: Monitoring
A7: Brake pipe corrosion (both sides) | B7: Medium | C7: 45474 | D7: 46155 | E7: Advisory recurring since 2024 MOTs. Not failure yet. | F7: Workshop inspection. Replace if pitted. Wire brush + rust treat if only surface. | G7: 150 | H7: Monitoring
A8: Check Viscous Coupling Unit (VCU) | B8: Medium | C8: 46095 | D8: 46155 | E8: Tested at purchase - no shuddering on tight turns. Healthy for now. | F8: Can seize and destroy IRD + rear diff. Replace preventatively if any signs of binding. | G8: 350 | H8: Resolved
A9: Central stop lamp not working | B9: Low | C9: 45474 | D9: 46155 | E9: Advisory since 2024 MOT. Likely corroded contacts per friend. | F9: DIY clean contacts or replace bulb. Trivial fix. | G9: 5 | H9: Resolved
A10: Instrument cluster backlight | B10: Low | C10: 46095 | D10: 46124 | E10: Speedometer backlight not illuminating. £50 off purchase price for this. | F10: Check fuse first, then bulbs behind cluster. DIY or workshop £30-50. | G10: 50 | H10: Resolved
A11: Fuel cap (temporary fix) | B11: Medium | C11: 46095 | D11: 46125 | E11: Flexi cap with snapped plastic tabs, on temporary fix. | F11: Order proper replacement cap from Amazon/eBay. | G11: 12 | H11: Resolved
A12: Tyre condition - front | B12: Low | C12: 46095 | D12: 46155 | E12: Not measured yet. Log in Tyre Log. | F12: Replace pair if tread <3mm or aged >6 years. | G12: 200 | H12: Monitoring
A13: Tyre condition - rear | B13: Low | C13: 46095 | D13: 46155 | E13: Not measured yet. Log in Tyre Log. | F13: Replace pair if tread <3mm or aged >6 years. | G13: 200 | H13: Monitoring
A14: Rust / bodywork | B14: Low | C14: 46095 | D14: 46155 | E14: Check regularly, especially sills, wheel arches, rear tailgate hinges. | F14: Touch up with paint pen. Underseal if significant. | G14: 100 | H14: Monitoring
A15: Hill Descent Control light warning | B15: Low | C15: 46193 | E15: HDC warning lights up often after ignition | F15: Check HDC cables under the gaiter, check throttle cable freeplay, check OBD codes - fixed the connection under gaiter and reverse gear switch, which was feeding the system for HDC as well. | H15: Resolved
F32: Total potential cost (worst case) | G32: =SUM(G5:G26) -> 1647

Sheet Equipment
A1: Equipment, Tools & Spares Inventory
A2: Everything you own for the car. Order needed items (marked "On order" / "To order").
A4: Item | B4: Category | C4: Purchased | D4: Source | E4: Cost (£) | F4: Where Stored | G4: Status | H4: Notes
A5: NOCO Genius5 battery charger/maintainer | B5: Maintenance | D5: Amazon | E5: 75 | F5: Home / boot | G5: Owned | H5: For extended parked periods. Also rejuvenates aged batteries.
A6: NOCO Boost GB40 jump starter pack | B6: Emergency | D6: Amazon | E6: 90 | F6: Boot | G6: Owned | H6: Portable jump pack - 12V, up to 6L petrol / 3L diesel.
A7: Replacement fuel cap | B7: Spare part | D7: Amazon / eBay | E7: 12 | F7: Fitted | G7: Owned | H7: Search "Freelander 1 fuel cap".
A8: Tyre pressure gauge (digital) | B8: Tool | D8: Amazon / Halfords | E8: 15 | F8: Glovebox | G8: Owned | H8: Accurate to 0.5 PSI recommended.
A9: Tyre tread depth gauge | B9: Tool | D9: Amazon / Halfords | E9: 5 | F9: Glovebox | G9: Owned | H9: 20p coin works too but gauge is accurate.
A10: 12V tyre inflator | B10: Tool | D10: Amazon / Halfords | E10: 35 | F10: Boot | G10: Owned | H10: Digital preset if possible.
A11: Jump leads (heavy duty) | B11: Emergency | D11: Amazon / Halfords | E11: 25 | F11: Boot | G11: Owned | H11: Redundant if GB40 works, but good backup.
A12: Warning triangle | B12: Safety | D12: Amazon / Halfords | E12: 8 | F12: Boot | G12: To order | H12: Legally required in many EU countries, useful at home.
A13: Hi-vis vest | B13: Safety | D13: Amazon / Halfords | E13: 5 | F13: Driver door pocket | G13: To order | H13: Keep in cabin, not boot.
A14: First aid kit | B14: Safety | D14: Amazon / Halfords | E14: 15 | F14: Boot / glovebox | G14: Owned
A15: Microfibre cloths (pack) | B15: Cleaning | D15: Amazon / Halfords | E15: 8 | F15: Boot | G15: Owned
A16: Leather cleaner + conditioner | B16: Cleaning | D16: Amazon (Gliptone or similar) | E16: 20 | F16: Home | G16: To order | H16: For cream leather interior.
A17: Screenwash concentrate | B17: Fluid | D17: Amazon / Halfords | E17: 8 | F17: Boot | G17: Owned | H17: Mix per label - summer/winter dilution differs.
A18: Engine oil (5L, 5W-30 or 10W-40) | B18: Fluid | D18: Halfords / Eurocarparts | E18: 30 | F18: Home | G18: To order | H18: Top-up spare. Match spec to what garage uses.
A19: Basic socket set + screwdrivers | B19: Tool | D19: Amazon / Halfords | E19: 40 | F19: Home | G19: Owned | H19: If not already owned.
A20: Torch (LED, rechargeable) | B20: Tool | D20: Amazon | E20: 20 | F20: Glovebox | G20: Owned | H20: For roadside checks at night.
A21: Axle stands | B21: Maintenance | D21: Amazon | E21: 30 | F21: Boot | G21: Owned
A22: Jack | B22: Maintenance | D22: Halfords / Eurocarparts | E22: 50 | F22: Boot | G22: Owned
A23: Mechanic toolset + wheel torque + ratchet spanners | B23: Tool | D23: Amazon | E23: 150 | F23: Boot | G23: Owned
D27: Total (owned + on order + to order) | E27: =SUM(E5:E25) -> 641
D28: Owned only | E28: =SUMIFS(E5:E25,G5:G25,"Owned") -> 578
D29: Outstanding spend (to order) | E29: =SUMIFS(E5:E25,G5:G25,"To order")+SUMIFS(E5:E25,G5:G25,"On order") -> 63
